<?xml version="1.0" ?>
<robot name="myrover" xmlns:xacro="http://ros.org/wiki/xacro">

  <xacro:include filename="$(find rover)/urdf/colors.xacro"/>
  <xacro:include filename="$(find rover)/urdf/myrover.gazebo.xacro"/>


  <link name="base_footprint"/>


  <joint name="base_joint" type="fixed">
    <parent link="base_footprint"/>
    <child link="base_link" />
    <origin xyz="0 0 0.010" rpy="0 0 0"/>
  </joint>


  <link name="base_link">
	<visual>
      <origin xyz="-0.27 0 0.17" rpy="0 0 0"/>
      <geometry>
        <box size="0.02 0.35 0.3"/>
      </geometry>
      <material name="orange"/>
    </visual>
    <visual>
      <origin xyz="-0.085 0.165 0.17" rpy="0 0 1.57"/>
      <geometry>
        <box size="0.02 0.35 0.3"/>
      </geometry>
      <material name="orange"/>
    </visual>
    <visual>
      <origin xyz="-0.085 -0.165 0.17" rpy="0 0 1.57"/>
      <geometry>
        <box size="0.02 0.35 0.3"/>
      </geometry>
      <material name="orange"/>
    </visual>
    
    <collision>
      <origin xyz="-0.27 0 0.17" rpy="0 0 0"/>
      <geometry>
        <box size="0.02 0.35 0.3"/>
      </geometry>
      <material name="orange"/>
    </collision>
    <collision>
      <origin xyz="-0.085 0.165 0.17" rpy="0 0 1.57"/>
      <geometry>
        <box size="0.02 0.35 0.3"/>
      </geometry>
      <material name="orange"/>
    </collision>
    <collision>
      <origin xyz="-0.085 -0.165 0.17" rpy="0 0 1.57"/>
      <geometry>
        <box size="0.02 0.35 0.3"/>
      </geometry>
      <material name="orange"/>
    </collision>
    
    <inertial>
      <origin xyz="0 0 0" rpy="0 0 0"/>
      <mass value="2"/>
      <inertia ixx="0.035416666666667" ixy="0" ixz="0"
               iyy="0.035416666666667" iyz="0"
               izz="0.040833333333333" />
    </inertial>
  </link>



  <joint name="wheel_left_joint" type="continuous">
    <parent link="base_link"/>
    <child link="wheel_left_link"/>
    <origin xyz="0.0 0.194 0.06" rpy="-1.57 0 0"/>
    <axis xyz="0 0 1"/>
  </joint>



  <link name="wheel_left_link">
    <visual>
      <origin xyz="0 0 0" rpy="0 0 0"/>
      <geometry>
        <!--mesh filename="package://turtlebot3_description/meshes/wheels/left_tire.stl" scale="0.001 0.001 0.001"/-->
        <cylinder length="0.018" radius="0.06"/>
      </geometry>
      <material name="dark"/>
    </visual>

    <collision>
      <origin xyz="0 0 0" rpy="0 0 0"/>
      <geometry>
        <cylinder length="0.018" radius="0.06"/>
      </geometry>
    </collision>

    <inertial>
      <origin xyz="0 0 0" />
      <mass value="2.8498940e-02" />
      <inertia ixx="1.1175580e-05" ixy="-4.2369783e-11" ixz="-5.9381719e-09"
               iyy="1.1192413e-05" iyz="-1.4400107e-11"
               izz="2.0712558e-05" />
      </inertial>
  </link>

  <joint name="wheel_right_joint" type="continuous">
    <parent link="base_link"/>
    <child link="wheel_right_link"/>
    <origin xyz="0.0 -0.194 0.06" rpy="-1.57 0 0"/>
    <axis xyz="0 0 1"/>
  </joint>

  <link name="wheel_right_link">
    <visual>
      <origin xyz="0 0 0" rpy="0 0 0"/>
      <geometry>
        <!--mesh filename="package://turtlebot3_description/meshes/wheels/right_tire.stl" scale="0.001 0.001 0.001"/-->
        <cylinder length="0.018" radius="0.06"/>
      </geometry>
      <material name="dark"/>
    </visual>

    <collision>
      <origin xyz="0 0 0" rpy="0 0 0"/>
      <geometry>
        <cylinder length="0.018" radius="0.06"/>
      </geometry>
    </collision>

    <inertial>
      <origin xyz="0 0 0" />
      <mass value="2.8498940e-02" />
      <inertia ixx="1.1175580e-05" ixy="-4.2369783e-11" ixz="-5.9381719e-09"
               iyy="1.1192413e-05" iyz="-1.4400107e-11"
               izz="2.0712558e-05" />
      </inertial>
  </link>



  <joint name="caster_back_right_joint" type="fixed">
    <parent link="base_link"/>
    <child link="caster_back_right_link"/>
    <origin xyz="-0.277 -0.064 -0.004" rpy="-1.57 0 0"/>
  </joint>





  <link name="caster_back_right_link">
    <collision>
      <origin xyz="0 0.001 0" rpy="0 0 0"/>
      <geometry>
        <box size="0.030 0.009 0.020"/>
      </geometry>
    </collision>

	<visual>
      <origin xyz="0 0.001 0" rpy="0 0 0"/>
      <geometry>
        <box size="0.030 0.009 0.020"/>
      </geometry>
    </visual>
    
    <inertial>
      <origin xyz="0 0 0" />
      <mass value="0.005" />
      <inertia ixx="0.001" ixy="0.0" ixz="0.0"
               iyy="0.001" iyz="0.0"
               izz="0.001" />
    </inertial>
  </link>

  <joint name="caster_back_left_joint" type="fixed">
    <parent link="base_link"/>
    <child link="caster_back_left_link"/>
    <origin xyz="-0.277 0.064 -0.004" rpy="-1.57 0 0"/>
  </joint>

  <link name="caster_back_left_link">
    <collision>
      <origin xyz="0 0.001 0" rpy="0 0 0"/>
      <geometry>
        <box size="0.030 0.009 0.020"/>
      </geometry>
    </collision>

	<visual>
      <origin xyz="0 0.001 0" rpy="0 0 0"/>
      <geometry>
        <box size="0.030 0.009 0.020"/>
      </geometry>
    </visual>
    
    <inertial>
      <origin xyz="0 0 0" />
      <mass value="0.005" />
      <inertia ixx="0.001" ixy="0.0" ixz="0.0"
               iyy="0.001" iyz="0.0"
               izz="0.001" />
    </inertial>
  </link>


  <link name="base_scan">
    <visual>
      <origin xyz="0 0 0" rpy="0 0 0"/>
      <geometry>
        <!--mesh filename="package://turtlebot3_description/meshes/sensors/lds.stl" scale="0.001 0.001 0.001"/-->
        <cylinder length="0.0315" radius="0.055"/>
      </geometry>
      <material name="dark"/>
    </visual>

    <collision>
      <origin xyz="0.015 0 -0.0065" rpy="0 0 0"/>
      <geometry>
        <cylinder length="0.0315" radius="0.055"/>
      </geometry>
    </collision>

    <inertial>
      <mass value="0.114" />
      <origin xyz="0 0 0" />
      <inertia ixx="0.001" ixy="0.0" ixz="0.0"
               iyy="0.001" iyz="0.0"
               izz="0.001" />
    </inertial>
  </link>
  
  <joint name="scan_joint" type="fixed">
    <parent link="base_link"/>
    <child link="base_scan"/>
    <origin xyz="-0.064 0 0.35" rpy="0 0 0"/>
  </joint>

</robot>
