<?xml version="1.0"?>
<robot name="myRobot">

    <material name="blue">
        <color rgba="0 0 0.8 1"/>
    </material>

    <material name="white">
        <color rgba="1 1 1 1"/>
    </material>

    <material name="green">
        <color rgba="0 0.8 0 1"/>
    </material>

    <material name="red">
        <color rgba="0.8 0 0 1"/>
    </material>



    <link name="base_link">
        <origin rpy="0 0 0" xyz="0 0 0"/>
    </link>


    <link name="back">
        <visual>
            <geometry>
                <box size="0.05 0.5 0.7"/>
            </geometry>
            <origin rpy="0 0 0" xyz="0 0 0"/>
            <material name="blue"/>
        </visual>
        <collision>
            <geometry>
                <box size="0.05 0.5 0.7"/>
            </geometry>
        </collision>
        <inertial>
            <mass value="0.5"/>
            <inertia ixx="0.030833333" ixy="0.0" ixz="0.0" 
                     iyy="0.020520833" iyz="0.0" 
                     izz="0.010520833"/>
        </inertial>
    </link>

    <link name="right">
        <visual>
            <geometry>
                <box size="0.05 0.5 0.7"/>
            </geometry>
            <origin rpy="0 0 1.57075" xyz="0 0 0"/>
            <material name="blue"/>
        </visual>
        <collision>
            <geometry>
                <box size="0.17 0.5 0.85"/>
            </geometry>
            <origin rpy="0 0 1.57075" xyz="0 -0.11 -0.075"/>
        </collision>
        <inertial>
            <mass value="0.5"/>
            <inertia ixx="0.030833333" ixy="0.0" ixz="0.0" iyy="0.020520833" iyz="0.0" izz="0.010520833"/>
        </inertial>
    </link>

    <link name="left">
        <visual>
            <geometry>
                <box size="0.05 0.5 0.7"/>
            </geometry>
            <origin rpy="0 0 1.57075" xyz="0 0 0"/>
            <material name="blue"/>
        </visual>
        <collision>
            <geometry>
                <box size="0.25 0.5 0.85"/>
            </geometry>
            <origin rpy="0 0 1.57075" xyz="0 0.07 -0.075"/>
        </collision>
        <inertial>
            <mass value="0.5"/>
            <inertia ixx="0.030833333" ixy="0.0" ixz="0.0" iyy="0.020520833" iyz="0.0" izz="0.010520833"/>
        </inertial>
    </link>

    
    <link name="left_leg">
        <visual>
            <geometry>
                <box size="0.6 0.1 0.2"/>
            </geometry>
            <origin rpy="0 1.57075 0" xyz="0 0 0"/>
            <material name="white"/>
        </visual>
    </link>


    <link name="left_wheels_holder">
        <visual>
            <geometry>
                <box size="0.1 0.2 0.5"/>
            </geometry>
            <origin rpy="0 1.57075 0" xyz="0 0 0"/>
            <material name="white"/>
        </visual>
    </link>

    <link name="right_leg">
        <visual>
            <geometry>
                <box size="0.6 0.1 0.2"/>
            </geometry>
            <origin rpy="0 1.57075 0" xyz="0 0 0"/>
            <material name="white"/>
        </visual>
    </link>


    <link name="right_wheels_holder">
        <visual>
            <geometry>
                <box size="0.1 0.2 0.5"/>
            </geometry>
            <origin rpy="0 1.57075 0" xyz="0 0 0"/>
            <material name="white"/>
        </visual>
    </link>

    <link name="left_wheel_main">
        <visual>
            <geometry>
                <cylinder length="0.070" radius="0.1"/>
            </geometry>
            <origin rpy="1.57075 0 0" xyz="0 0 0"/>
            <material name="green"/>
        </visual>
    </link>

    <link name="right_wheel_main">
        <visual>
            <geometry>
            <cylinder length="0.070" radius="0.1"/>
            </geometry>
            <origin rpy="1.57075 0 0" xyz="0 0 0"/>
            <material name="green"/>
        </visual>
    </link>



    <link name="caster_right_front">
        <visual>
            <geometry>
                <sphere radius="0.05"/>
            </geometry>
            <origin rpy="1.57075 0 0" xyz="0 0 0"/>
            <material name="red"/>
        </visual>
    </link>


    <link name="caster_right_back">
        <visual>
            <geometry>
                <sphere radius="0.05"/>
            </geometry>
            <origin rpy="1.57075 0 0" xyz="0 0 0"/>
            <material name="red"/>
        </visual>
    </link>

    <link name="caster_left_front">
        <visual>
            <geometry>
                <sphere radius="0.05"/>
            </geometry>
            <origin rpy="1.57075 0 0" xyz="0 0 0"/>
            <material name="red"/>
        </visual>
    </link>

    <link name="caster_left_back">
        <visual>
            <geometry>
                <sphere radius="0.05"/>
            </geometry>
            <origin rpy="1.57075 0 0" xyz="0 0 0"/>
            <material name="red"/>
        </visual>
    </link>



    <joint name="Base_link_to_back" type="fixed">
        <parent link="base_link"/>
        <child link="back"/>
        <origin xyz="-0.23 0 0.5"/>
    </joint>

    <joint name="Base_link_to_right" type="fixed">
        <parent link="base_link"/>
        <child link="right"/>
        <origin xyz="0 -0.23 0.5"/>
    </joint>

    <joint name="Base_link_to_left" type="fixed">
        <parent link="base_link"/>
        <child link="left"/>
        <origin xyz="0 0.23 0.5"/>
    </joint>

    <joint name="Left_to_left_leg" type="prismatic">
        <parent link="left"/>
        <child link="left_leg"/>
        <limit effort="1000.0" lower="-0.3" upper="0" velocity="0.5"/>
        <axis xyz="0 0 1" />
        <origin xyz="0 0.03 -0.15"/>
    </joint>

    <joint name="Left_leg_to_left_wheels_holder" type="fixed">
        <parent link="left_leg"/>
        <child link="left_wheels_holder"/>
        <origin xyz="0 0.07 -0.25"/>
    </joint>

    <joint name="Left_wheels_holder_to_left_wheel_main" type="continuous">
        <parent link="left_wheels_holder"/>
        <child link="left_wheel_main"/>
        <axis xyz="0 1 0"/>
        <origin xyz="0 0.04 0"/>
    </joint>

    <joint name="Left_leg_holder_to_caster_front" type="fixed">
        <parent link="left_wheels_holder"/>
        <child link="caster_left_front"/>
        <origin xyz="0.2 -0.04 -0.05"/>
    </joint>

    <joint name="Left_leg_holder_to_caster_back" type="fixed">
        <parent link="left_wheels_holder"/>
        <child link="caster_left_back"/>
        <origin xyz="-0.2 -0.04 -0.05"/>
    </joint>




    <joint name="Right_to_right_leg" type="prismatic">
        <parent link="right"/>
        <child link="right_leg"/>
        <limit effort="1000.0" lower="-0.3" upper="0" velocity="0.5"/>
        <axis xyz="0 0 1" />
        <origin xyz="0 -0.03 -0.15"/>
    </joint>

    <joint name="Right_leg_to_right_leg_holder" type="fixed">
        <parent link="right_leg"/>
        <child link="right_wheels_holder"/>
        <origin xyz="0 -0.07 -0.25"/>
    </joint>

    <joint name="Right_wheels_holder_to_right_wheel_main" type="continuous">
        <parent link="right_wheels_holder"/>
        <child link="right_wheel_main"/>
        <axis xyz="0 1 0"/>
        <origin xyz="0 -0.04 0"/>
    </joint>

    <joint name="Right_leg_holder_to_caster_front" type="fixed">
        <parent link="right_wheels_holder"/>
        <child link="caster_right_front"/>
        <origin xyz="0.2 -0.04 -0.05"/>
    </joint>

    <joint name="Right_leg_holder_to_caster_back" type="fixed">
        <parent link="right_wheels_holder"/>
        <child link="caster_right_back"/>
        <origin xyz="-0.2 -0.04 -0.05"/>
    </joint>


</robot>